<robot name="meca_500_r3" xmlns:xacro="http://ros.org/wiki/xacro">
  <link name="world"/>  
  <joint name="world_A" type="fixed">
    <parent link="world"/>
    <child link="meca_base_link_A"/>
  </joint>
  <!-- Base link is the center of the robot's bottom plate -->
  <link name="meca_base_link_A">
    <visual>
      <origin xyz="0 0 0" rpy="0 0 0" />
      <geometry>
        <mesh filename="package://mecademic_description/meshes/meca_500_r3_base.dae" />
      </geometry>
    </visual>
    <collision>
      <origin rpy="-0.00464229562531 1.241639409 -0.00331992768483" xyz="0.002912665 2.5933825e-05 0.03195115"/>
      <geometry>
        <cylinder length="0.0247681427348" radius="0.069277"/>
      </geometry>
    </collision>
    <collision>
      <origin rpy="-0.00464229562531 1.241639409 -0.00331992768483" xyz="-0.008807 0.000007 0.027948"/>
      <geometry>
        <sphere radius="0.069277"/>
      </geometry>
    </collision>
    <collision>
      <origin rpy="-0.00464229562531 1.241639409 -0.00331992768483" xyz="0.014632 0.000045 0.035954"/>
      <geometry>
        <sphere radius="0.069277"/>
      </geometry>
    </collision>
    <inertial>
      <mass value="1"/>
      <inertia ixx="0.01" ixy="0" ixz="0" iyy="0.01" iyz="0" izz="0.01"/>
    </inertial>
  </link>

  <gazebo>
      <plugin filename="libxbot2_gz_joint_server.so" name="xbot2_gz_joint_server">
         <pid>
            <pid name="meca_axis_1_joint_A" profile="small_mot"/>
            <pid name="meca_axis_2_joint_A" profile="small_mot"/>
            <pid name="meca_axis_3_joint_A" profile="small_mot"/>
            <pid name="meca_axis_4_joint_A" profile="small_mot"/>
            <pid name="meca_axis_5_joint_A" profile="small_mot"/>
            <pid name="meca_axis_6_joint_A" profile="small_mot"/>
         </pid>
         <gain d="5" name="small_mot" p="100"/>
      </plugin>
   </gazebo>

  <!-- Joint 1 -->
  <link name="meca_axis_1_link_A">
    <visual>
      <origin xyz="0 0 0" rpy="0 0 0" />
      <geometry>
        <mesh filename="package://mecademic_description/meshes/meca_500_r3_j1.dae" />
      </geometry>
    </visual>
    <collision>
      <origin rpy="-1.5643390872 0.00108905813092 -0.00108204843032" xyz="1.404e-07 -0.00017605 0.03168225"/>
      <geometry>
        <cylinder length="0.0388249324419" radius="0.0530516"/>
      </geometry>
    </collision>
    <collision>
      <origin rpy="-1.5643390872 0.00108905813092 -0.00108204843032" xyz="-0.000021 -0.019588 0.031557"/>
      <geometry>
        <sphere radius="0.0530516"/>
      </geometry>
    </collision>
    <collision>
      <origin rpy="-1.5643390872 0.00108905813092 -0.00108204843032" xyz="0.000021 0.019236 0.031808"/>
      <geometry>
        <sphere radius="0.0530516"/>
      </geometry>
    </collision>
    <inertial>
      <mass value="1"/>
      <inertia ixx="0.01" ixy="0" ixz="0" iyy="0.01" iyz="0" izz="0.01"/>
    </inertial>
  </link>

  <joint name="meca_axis_1_joint_A" type="revolute">
    <origin xyz="0.012498 0 0.091" rpy="0 0 0" />
    <parent link="meca_base_link_A" />
    <child link="meca_axis_1_link_A" />
    <axis xyz="0 0 1" />
    <limit effort="10.0" velocity="2.61799" lower="-3.05433" upper="3.05433" />
  </joint>

  <!-- Joint 2 -->
  <link name="meca_axis_2_link_A">
    <visual>
      <origin xyz="0 0 0" rpy="0 0 0" />
      <geometry>
        <mesh filename="package://mecademic_description/meshes/meca_500_r3_j2.dae" />
      </geometry>
    </visual>
    <collision>
      <origin rpy="3.14150631803 -0.0666872950524 -3.13900434911" xyz="-0.007204205 2.561655e-06 0.07263715"/>
      <geometry>
        <cylinder length="0.121249210008" radius="0.0578403"/>
      </geometry>
    </collision>
    <collision>
      <origin rpy="3.14150631803 -0.0666872950524 -3.13900434911" xyz="-0.003164 0.000008 0.133127"/>
      <geometry>
        <sphere radius="0.0578403"/>
      </geometry>
    </collision>
    <collision>
      <origin rpy="3.14150631803 -0.0666872950524 -3.13900434911" xyz="-0.011244 -0.000003 0.012147"/>
      <geometry>
        <sphere radius="0.0578403"/>
      </geometry>
    </collision>
    <inertial>
      <mass value="1"/>
      <inertia ixx="0.01" ixy="0" ixz="0" iyy="0.01" iyz="0" izz="0.01"/>
    </inertial>
  </link>

  <joint name="meca_axis_2_joint_A" type="revolute">
    <origin xyz="0 0 0.044" rpy="0 0 0" />
    <parent link="meca_axis_1_link_A" />
    <child link="meca_axis_2_link_A" />
    <axis xyz="0 1 0" />
    <limit effort="10.0" velocity="2.61799" lower="-1.22173048" upper="1.5708" />
  </joint>

  <!-- Joint 3 -->
  <link name="meca_axis_3_link_A">
    <visual>
      <origin xyz="0 0 0" rpy="0 0 0" />
      <geometry>
        <mesh filename="package://mecademic_description/meshes/meca_500_r3_j3.dae" />
      </geometry>
    </visual>
    <collision>
      <origin rpy="-0.0775632999618 0.486298597709 -0.0192491912301" xyz="0.009983498 -0.000990284 0.020095595"/>
      <geometry>
        <cylinder length="0.0408120816515" radius="0.0503272"/>
      </geometry>
    </collision>
    <collision>
      <origin rpy="-0.0775632999618 0.486298597709 -0.0192491912301" xyz="0.000447 -0.002388 0.002109"/>
      <geometry>
        <sphere radius="0.0503272"/>
      </geometry>
    </collision>
    <collision>
      <origin rpy="-0.0775632999618 0.486298597709 -0.0192491912301" xyz="0.019520 0.000408 0.038082"/>
      <geometry>
        <sphere radius="0.0503272"/>
      </geometry>
    </collision>
    <inertial>
      <mass value="1"/>
      <inertia ixx="0.01" ixy="0" ixz="0" iyy="0.01" iyz="0" izz="0.01"/>
    </inertial>
  </link>

  <joint name="meca_axis_3_joint_A" type="revolute">
    <origin xyz="0 0 0.135" rpy="0 0 0" />
    <parent link="meca_axis_2_link_A" />
    <child link="meca_axis_3_link_A" />
    <axis xyz="0 1 0" />
    <limit effort="10.0" velocity="3.14159" lower="-2.35619" upper="1.22173048" />
  </joint>

  <!-- Joint 4 -->
  <link name="meca_axis_4_link_A">
    <visual>
      <origin xyz="0 0 0" rpy="0 0 0" />
      <geometry>
        <mesh filename="package://mecademic_description/meshes/meca_500_r3_j4.dae" />
      </geometry>
    </visual>
    <collision>
      <origin rpy="-1.61527511752 1.5509782436 -1.59546790677" xyz="0.1018437 -0.00037629375 0.0004856635"/>
      <geometry>
        <cylinder length="0.0362997282424" radius="0.0387182"/>
      </geometry>
    </collision>
    <collision>
      <origin rpy="-1.61527511752 1.5509782436 -1.59546790677" xyz="0.083697 -0.000736 0.000502"/>
      <geometry>
        <sphere radius="0.0387182"/>
      </geometry>
    </collision>
    <collision>
      <origin rpy="-1.61527511752 1.5509782436 -1.59546790677" xyz="0.119990 -0.000017 0.000470"/>
      <geometry>
        <sphere radius="0.0387182"/>
      </geometry>
    </collision>
    <inertial>
      <mass value="1"/>
      <inertia ixx="0.01" ixy="0" ixz="0" iyy="0.01" iyz="0" izz="0.01"/>
    </inertial>
  </link>

  <joint name="meca_axis_4_joint_A" type="revolute">
    <origin xyz="0 0 0.038" rpy="0 0 0" />
    <parent link="meca_axis_3_link_A" />
    <child link="meca_axis_4_link_A" />
    <axis xyz="1 0 0" />
    <limit effort="10.0" velocity="5.23599" lower="-2.96706" upper="2.96706" />
  </joint>

  <!-- Joint 5 -->
  <link name="meca_axis_5_link_A">
    <visual>
      <origin xyz="0 0 0" rpy="0 0 0" />
      <geometry>
        <mesh filename="package://mecademic_description/meshes/meca_500_r3_j5.dae" />
      </geometry>
    </visual>
    <collision>
      <origin rpy="-1.56738494938 1.42197043963 -1.41859762505" xyz="0.022533785 0.002385127 -0.000338951"/>
      <geometry>
        <cylinder length="0.0337980384654" radius="0.0373293"/>
      </geometry>
    </collision>
    <collision>
      <origin rpy="-1.56738494938 1.42197043963 -1.41859762505" xyz="0.005822 -0.000121 -0.000347"/>
      <geometry>
        <sphere radius="0.0373293"/>
      </geometry>
    </collision>
    <collision>
      <origin rpy="-1.56738494938 1.42197043963 -1.41859762505" xyz="0.039246 0.004891 -0.000330"/>
      <geometry>
        <sphere radius="0.0373293"/>
      </geometry>
    </collision>
    <inertial>
      <mass value="1"/>
      <inertia ixx="0.01" ixy="0" ixz="0" iyy="0.01" iyz="0" izz="0.01"/>
    </inertial>
  </link>

  <joint name="meca_axis_5_joint_A" type="revolute">
    <origin xyz="0.12 0 0" rpy="0 0 0" />
    <parent link="meca_axis_4_link_A" />
    <child link="meca_axis_5_link_A" />
    <axis xyz="0 1 0" />
    <limit effort="10.0" velocity="5.23599" lower="-2.00713" upper="2.00713" />
  </joint>

  <!-- Joint 6 -->
  <link name="meca_axis_6_link_A">
    <visual>
      <origin xyz="0 0 0" rpy="0 0 0" />
      <geometry>
        <mesh filename="package://mecademic_description/meshes/meca_500_r3_j6.dae" />
      </geometry>
    </visual>
    <collision>
      <origin rpy="3.14152943169 -0.0847389814668 -3.14010139052" xyz="-0.002858345 7.482995e-07 -1.9915e-05"/>
      <geometry>
        <cylinder length="0.00588946257883" radius="0.0134707"/>
      </geometry>
    </collision>
    <collision>
      <origin rpy="3.14152943169 -0.0847389814668 -3.14010139052" xyz="-0.002609 0.000001 0.002914"/>
      <geometry>
        <sphere radius="0.0134707"/>
      </geometry>
    </collision>
    <collision>
      <origin rpy="3.14152943169 -0.0847389814668 -3.14010139052" xyz="-0.003108 0.000001 -0.002954"/>
      <geometry>
        <sphere radius="0.0134707"/>
      </geometry>
    </collision>
    <inertial>
      <mass value="1"/>
      <inertia ixx="0.01" ixy="0" ixz="0" iyy="0.01" iyz="0" izz="0.01"/>
    </inertial>
  </link>

  <joint name="meca_axis_6_joint_A" type="revolute">
    <origin xyz="0.07 0 0" rpy="0 0 0" />
    <parent link="meca_axis_5_link_A" />
    <child link="meca_axis_6_link_A" />
    <axis xyz="1 0 0" />
    <limit effort="10.0" velocity="8.72665" lower="-4.712" upper="4.712" />
  </joint>


<!-- 2nd ROBOT -->
 <joint name="world_to_meca_B" type="fixed">
      <origin xyz="0.2 0.3 0" rpy="0 0 0"/>
      <parent link="world"/>
      <child link="base_link_B"/>
    </joint>

  <gazebo>
      <plugin filename="libxbot2_gz_joint_server.so" name="xbot2_gz_joint_server">
          <pid>
            <pid name="J1_B" profile="small_mot"/>
            <pid name="meca_axis_1_joint_B" profile="small_mot"/>
            <pid name="meca_axis_2_joint_B" profile="small_mot"/>
            <pid name="meca_axis_3_joint_B" profile="small_mot"/>
            <pid name="meca_axis_4_joint_B" profile="small_mot"/>
            <pid name="meca_axis_5_joint_B" profile="small_mot"/>
            <pid name="meca_axis_6_joint_B" profile="small_mot"/>
          </pid>
          <gain d="5" name="small_mot" p="100"/>
      </plugin>
    </gazebo>
  
  <link name="base_link_B">
    <inertial>
      <mass value="10.0"/>
      <inertia ixx="1.0e-03" ixy="0.0" ixz="0.0" iyy="1.0e-03" iyz="0.0" izz="1.0e-03"/>
    </inertial>
  </link>

  <joint name="J1_B" type="revolute">
    <axis xyz="0 0 1"/>
    <limit effort="1000.0" lower="-6.28" upper="6.28" velocity="100"/>
    <origin rpy="0 0 0" xyz="0.0 0.0 0.05"/>
    <parent link="base_link_B"/>
    <child link="L_1_B"/>
  </joint>

  <link name="L_1_B">
    <visual>
      <geometry>
        <cylinder length="0.1" radius="0.1"/>
      </geometry>
      <material name="blue">
        <color rgba="0 0 .8 1"/>
      </material>
    </visual>
    <collision>
      <origin xyz="0 0 0" rpy="0 0 0" />
      <geometry>
        <cylinder length="0.1" radius="0.1"/>
      </geometry>
    </collision>
  </link>

  <joint name="L_1_B_to_meca_base_link_B" type="fixed">
    <parent link="L_1_B"/>
    <child link="meca_base_link_B"/>
    <origin rpy="0 0.7854 0" xyz="0.0 0.0 0.1"/>
  </joint>

    <!-- Base link is the center of the robot's bottom plate -->
  <link name="meca_base_link_B">
    <visual>
      <origin xyz="0 0 0" rpy="0 0 0" />
      <geometry>
        <mesh filename="package://mecademic_description/meshes/meca_500_r3_base.dae" />
      </geometry>
    </visual>
    <collision>
      <origin rpy="-0.00464229562531 1.241639409 -0.00331992768483" xyz="0.002912665 2.5933825e-05 0.03195115"/>
      <geometry>
        <cylinder length="0.0247681427348" radius="0.069277"/>
      </geometry>
    </collision>
    <collision>
      <origin rpy="-0.00464229562531 1.241639409 -0.00331992768483" xyz="-0.008807 0.000007 0.027948"/>
      <geometry>
        <sphere radius="0.069277"/>
      </geometry>
    </collision>
    <collision>
      <origin rpy="-0.00464229562531 1.241639409 -0.00331992768483" xyz="0.014632 0.000045 0.035954"/>
      <geometry>
        <sphere radius="0.069277"/>
      </geometry>
    </collision>
    <inertial>
      <mass value="1"/>
      <inertia ixx="0.01" ixy="0" ixz="0" iyy="0.01" iyz="0" izz="0.01"/>
    </inertial>
  </link>

  <gazebo>
      <plugin filename="libxbot2_gz_joint_server.so" name="xbot2_gz_joint_server">
          <pid>
            <pid name="meca_axis_1_joint_B" profile="small_mot"/>
            <pid name="meca_axis_2_joint_B" profile="small_mot"/>
            <pid name="meca_axis_3_joint_B" profile="small_mot"/>
            <pid name="meca_axis_4_joint_B" profile="small_mot"/>
            <pid name="meca_axis_5_joint_B" profile="small_mot"/>
            <pid name="meca_axis_6_joint_B" profile="small_mot"/>
          </pid>
          <gain d="5" name="small_mot" p="100"/>
      </plugin>
    </gazebo>

  <!-- Joint 1 -->
  <link name="meca_axis_1_link_B">
    <visual>
      <origin xyz="0 0 0" rpy="0 0 0" />
      <geometry>
        <mesh filename="package://mecademic_description/meshes/meca_500_r3_j1.dae" />
      </geometry>
    </visual>
    <collision>
      <origin rpy="-1.5643390872 0.00108905813092 -0.00108204843032" xyz="1.404e-07 -0.00017605 0.03168225"/>
      <geometry>
        <cylinder length="0.0388249324419" radius="0.0530516"/>
      </geometry>
    </collision>
    <collision>
      <origin rpy="-1.5643390872 0.00108905813092 -0.00108204843032" xyz="-0.000021 -0.019588 0.031557"/>
      <geometry>
        <sphere radius="0.0530516"/>
      </geometry>
    </collision>
    <collision>
      <origin rpy="-1.5643390872 0.00108905813092 -0.00108204843032" xyz="0.000021 0.019236 0.031808"/>
      <geometry>
        <sphere radius="0.0530516"/>
      </geometry>
    </collision>
    <inertial>
      <mass value="1"/>
      <inertia ixx="0.01" ixy="0" ixz="0" iyy="0.01" iyz="0" izz="0.01"/>
    </inertial>
  </link>

  <joint name="meca_axis_1_joint_B" type="revolute">
    <origin xyz="0.012498 0 0.091" rpy="0 0 0" />
    <parent link="meca_base_link_B" />
    <child link="meca_axis_1_link_B" />
    <axis xyz="0 0 1" />
    <limit effort="10.0" velocity="2.61799" lower="-3.05433" upper="3.05433" />
  </joint>

  <!-- Joint 2 -->
  <link name="meca_axis_2_link_B">
    <visual>
      <origin xyz="0 0 0" rpy="0 0 0" />
      <geometry>
        <mesh filename="package://mecademic_description/meshes/meca_500_r3_j2.dae" />
      </geometry>
    </visual>
    <collision>
      <origin rpy="3.14150631803 -0.0666872950524 -3.13900434911" xyz="-0.007204205 2.561655e-06 0.07263715"/>
      <geometry>
        <cylinder length="0.121249210008" radius="0.0578403"/>
      </geometry>
    </collision>
    <collision>
      <origin rpy="3.14150631803 -0.0666872950524 -3.13900434911" xyz="-0.003164 0.000008 0.133127"/>
      <geometry>
        <sphere radius="0.0578403"/>
      </geometry>
    </collision>
    <collision>
      <origin rpy="3.14150631803 -0.0666872950524 -3.13900434911" xyz="-0.011244 -0.000003 0.012147"/>
      <geometry>
        <sphere radius="0.0578403"/>
      </geometry>
    </collision>
    <inertial>
      <mass value="1"/>
      <inertia ixx="0.01" ixy="0" ixz="0" iyy="0.01" iyz="0" izz="0.01"/>
    </inertial>
  </link>

  <joint name="meca_axis_2_joint_B" type="revolute">
    <origin xyz="0 0 0.044" rpy="0 0 0" />
    <parent link="meca_axis_1_link_B" />
    <child link="meca_axis_2_link_B" />
    <axis xyz="0 1 0" />
    <limit effort="10.0" velocity="2.61799" lower="-1.22173048" upper="1.5708" />
  </joint>

  <!-- Joint 3 -->
  <link name="meca_axis_3_link_B">
    <visual>
      <origin xyz="0 0 0" rpy="0 0 0" />
      <geometry>
        <mesh filename="package://mecademic_description/meshes/meca_500_r3_j3.dae" />
      </geometry>
    </visual>
    <collision>
      <origin rpy="-0.0775632999618 0.486298597709 -0.0192491912301" xyz="0.009983498 -0.000990284 0.020095595"/>
      <geometry>
        <cylinder length="0.0408120816515" radius="0.0503272"/>
      </geometry>
    </collision>
    <collision>
      <origin rpy="-0.0775632999618 0.486298597709 -0.0192491912301" xyz="0.000447 -0.002388 0.002109"/>
      <geometry>
        <sphere radius="0.0503272"/>
      </geometry>
    </collision>
    <collision>
      <origin rpy="-0.0775632999618 0.486298597709 -0.0192491912301" xyz="0.019520 0.000408 0.038082"/>
      <geometry>
        <sphere radius="0.0503272"/>
      </geometry>
    </collision>
    <inertial>
      <mass value="1"/>
      <inertia ixx="0.01" ixy="0" ixz="0" iyy="0.01" iyz="0" izz="0.01"/>
    </inertial>
  </link>

  <joint name="meca_axis_3_joint_B" type="revolute">
    <origin xyz="0 0 0.135" rpy="0 0 0" />
    <parent link="meca_axis_2_link_B" />
    <child link="meca_axis_3_link_B" />
    <axis xyz="0 1 0" />
    <limit effort="10.0" velocity="3.14159" lower="-2.35619" upper="1.22173048" />
  </joint>

  <!-- Joint 4 -->
  <link name="meca_axis_4_link_B">
    <visual>
      <origin xyz="0 0 0" rpy="0 0 0" />
      <geometry>
        <mesh filename="package://mecademic_description/meshes/meca_500_r3_j4.dae" />
      </geometry>
    </visual>
    <collision>
      <origin rpy="-1.61527511752 1.5509782436 -1.59546790677" xyz="0.1018437 -0.00037629375 0.0004856635"/>
      <geometry>
        <cylinder length="0.0362997282424" radius="0.0387182"/>
      </geometry>
    </collision>
    <collision>
      <origin rpy="-1.61527511752 1.5509782436 -1.59546790677" xyz="0.083697 -0.000736 0.000502"/>
      <geometry>
        <sphere radius="0.0387182"/>
      </geometry>
    </collision>
    <collision>
      <origin rpy="-1.61527511752 1.5509782436 -1.59546790677" xyz="0.119990 -0.000017 0.000470"/>
      <geometry>
        <sphere radius="0.0387182"/>
      </geometry>
    </collision>
    <inertial>
      <mass value="1"/>
      <inertia ixx="0.01" ixy="0" ixz="0" iyy="0.01" iyz="0" izz="0.01"/>
    </inertial>
  </link>

  <joint name="meca_axis_4_joint_B" type="revolute">
    <origin xyz="0 0 0.038" rpy="0 0 0" />
    <parent link="meca_axis_3_link_B" />
    <child link="meca_axis_4_link_B" />
    <axis xyz="1 0 0" />
    <limit effort="10.0" velocity="5.23599" lower="-2.96706" upper="2.96706" />
  </joint>

  <!-- Joint 5 -->
  <link name="meca_axis_5_link_B">
    <visual>
      <origin xyz="0 0 0" rpy="0 0 0" />
      <geometry>
        <mesh filename="package://mecademic_description/meshes/meca_500_r3_j5.dae" />
      </geometry>
    </visual>
    <collision>
      <origin rpy="-1.56738494938 1.42197043963 -1.41859762505" xyz="0.022533785 0.002385127 -0.000338951"/>
      <geometry>
        <cylinder length="0.0337980384654" radius="0.0373293"/>
      </geometry>
    </collision>
    <collision>
      <origin rpy="-1.56738494938 1.42197043963 -1.41859762505" xyz="0.005822 -0.000121 -0.000347"/>
      <geometry>
        <sphere radius="0.0373293"/>
      </geometry>
    </collision>
    <collision>
      <origin rpy="-1.56738494938 1.42197043963 -1.41859762505" xyz="0.039246 0.004891 -0.000330"/>
      <geometry>
        <sphere radius="0.0373293"/>
      </geometry>
    </collision>
    <inertial>
      <mass value="1"/>
      <inertia ixx="0.01" ixy="0" ixz="0" iyy="0.01" iyz="0" izz="0.01"/>
    </inertial>
  </link>

  <joint name="meca_axis_5_joint_B" type="revolute">
    <origin xyz="0.12 0 0" rpy="0 0 0" />
    <parent link="meca_axis_4_link_B" />
    <child link="meca_axis_5_link_B" />
    <axis xyz="0 1 0" />
    <limit effort="10.0" velocity="5.23599" lower="-2.00713" upper="2.00713" />
  </joint>

  <!-- Joint 6 -->
  <link name="meca_axis_6_link_B">
    <visual>
      <origin xyz="0 0 0" rpy="0 0 0" />
      <geometry>
        <mesh filename="package://mecademic_description/meshes/meca_500_r3_j6.dae" />
      </geometry>
    </visual>
    <collision>
      <origin rpy="3.14152943169 -0.0847389814668 -3.14010139052" xyz="-0.002858345 7.482995e-07 -1.9915e-05"/>
      <geometry>
        <cylinder length="0.00588946257883" radius="0.0134707"/>
      </geometry>
    </collision>
    <collision>
      <origin rpy="3.14152943169 -0.0847389814668 -3.14010139052" xyz="-0.002609 0.000001 0.002914"/>
      <geometry>
        <sphere radius="0.0134707"/>
      </geometry>
    </collision>
    <collision>
      <origin rpy="3.14152943169 -0.0847389814668 -3.14010139052" xyz="-0.003108 0.000001 -0.002954"/>
      <geometry>
        <sphere radius="0.0134707"/>
      </geometry>
    </collision>
    <inertial>
      <mass value="1"/>
      <inertia ixx="0.01" ixy="0" ixz="0" iyy="0.01" iyz="0" izz="0.01"/>
    </inertial>
  </link>

  <joint name="meca_axis_6_joint_B" type="revolute">
    <origin xyz="0.07 0 0" rpy="0 0 0" />
    <parent link="meca_axis_5_link_B" />
    <child link="meca_axis_6_link_B" />
    <axis xyz="1 0 0" />
    <limit effort="10.0" velocity="8.72665" lower="-4.712" upper="4.712" />
  </joint>

  <!-- BUFFERS -->
  <joint name="world_to_buffer" type="fixed">
    <origin xyz="0.2 0.1 0.1" rpy="0 0 0"/>
    <parent link="world"/>
    <child link="buffer_base_link"/>
  </joint>
  
  <link name="buffer_base_link"/>   

  <joint name="buffer_base_to_1" type="fixed">
    <origin xyz="0 0 0" rpy="0 0 0"/>
    <parent link="buffer_base_link"/>
    <child link="buffer_1"/>
  </joint>

  <link name="buffer_1"/>

  <joint name="buffer_base_to_2" type="fixed">
        <origin xyz="0.1 0.0 0" rpy="0 0 0"/>
        <parent link="buffer_base_link"/>
        <child link="buffer_2"/>
      </joint>

  <link name="buffer_2"/>

  <!-- CANDY MILL -->
  <joint name="world_to_mill" type="fixed">
    <origin xyz="0.45 0.3 0.1" rpy="0 0 0"/>
    <parent link="world"/>
    <child link="mill_base_link"/>
  </joint>
  
  <link name="mill_base_link"/>   

  <joint name="mill_base_to_stick" type="fixed">
    <origin xyz="0 0 0.15" rpy="0 0 0"/>
    <parent link="mill_base_link"/>
    <child link="mill_stick"/>
  </joint>

  <link name="mill_stick"/>

  <!-- SLIDERS -->
  <joint name="world_to_slider" type="fixed">
    <origin xyz="0.2 0 0.1" rpy="0 0 0"/>
    <parent link="world"/>
    <child link="slider_base_link"/>
  </joint>
  
  <link name="slider_base_link"/>   

  <joint name="slider_base_to_empty" type="fixed">
    <origin xyz="0 0 0" rpy="0 0 0"/>
    <parent link="slider_base_link"/>
    <child link="empty_container"/>
  </joint>

  <link name="empty_container"/>

  <joint name="sliders_base_to_lid" type="fixed">
        <origin xyz="0.1 0.0 0" rpy="0 0 0"/>
        <parent link="slider_base_link"/>
        <child link="lid"/>
      </joint>

  <link name="lid"/>

  <joint name="sliders_base_to_full" type="fixed">
        <origin xyz="0 -0.1 0" rpy="0 0 0"/>
        <parent link="slider_base_link"/>
        <child link="full_container"/>
      </joint>

  <link name="full_container"/>


</robot>