<robot name="meca_500_r3" xmlns:xacro="http://ros.org/wiki/xacro">
  <link name="world"/> 

  <joint name="world_to_base_A" type="fixed">
    <parent link="world"/>
    <child link="base_link_A"/>
    <origin rpy="0 0 0" xyz="0.3 -0.1 0.0"/>
  </joint>

  <gazebo>
      <plugin filename="libxbot2_gz_joint_server.so" name="xbot2_gz_joint_server">
         <pid>
            <pid name="J1_A" profile="small_mot"/>
            <pid name="meca_axis_1_joint_A" profile="small_mot"/>
            <pid name="meca_axis_2_joint_A" profile="small_mot"/>
            <pid name="meca_axis_3_joint_A" profile="small_mot"/>
            <pid name="meca_axis_4_joint_A" profile="small_mot"/>
            <pid name="meca_axis_5_joint_A" profile="small_mot"/>
            <pid name="meca_axis_6_joint_A" profile="small_mot"/>
         </pid>
         <gain d="5" name="small_mot" p="100"/>
      </plugin>
   </gazebo>

  <link name="base_link_A">
    <inertial>
      <mass value="10.0"/>
      <inertia ixx="1.0e-03" ixy="0.0" ixz="0.0" iyy="1.0e-03" iyz="0.0" izz="1.0e-03"/>
    </inertial>
  </link>

  <joint name="fixed_L_1_A" type="fixed">
    <parent link="base_link_A"/>
    <child link="L_1_A_stator"/>
    <origin xyz="0.0 0.0 0.06" rpy="0 0 0" />
  </joint>


  <link name="L_1_A_stator">
    <visual>
      <geometry>
        <box size="0.72 0.12 0.1"/>
      </geometry>
      <material name="blue">
        <color rgba="0 0 .8 1"/>
      </material>
      <origin xyz="0 0 0" rpy="0 0 0" />
    </visual>
    <collision>
      <origin xyz="0 0 0" rpy="0 0 0" />
      <geometry>
        <box size="0.72 0.12 0.1"/>
      </geometry>
    </collision>
  </link>

  <joint name="J1_A" type="prismatic">
    <axis xyz="1 0 0"/>
    <parent link="L_1_A_stator"/>
    <child link="L_1_A"/>
    <limit effort="1000.0" lower="-0.3" upper="0.3" velocity="100"/>
    <origin rpy="0 0 0" xyz="0 0 0.09"/>
  </joint>

  <link name="L_1_A">
    <visual>
      <geometry>
        <box size="0.2 0.2 0.04"/>
      </geometry>
      <material name="blue">
        <color rgba="0 0 .8 1"/>
      </material>
      <origin xyz="0 0 -0.02" rpy="0 0 0" />
    </visual>
    <collision>
      <origin xyz="0 0 -0.02" rpy="0 0 0" />
      <geometry>
        <box size="0.2 0.2 0.04"/>
      </geometry>
    </collision>
  </link>

  <joint name="L_1_A_to_meca_base_link_A" type="fixed">
    <parent link="L_1_A"/>
    <child link="meca_base_link_A"/>
    <origin rpy="0 1.571 1.571" xyz="0.0 0.05 0.05"/>
  </joint>

  <!-- Base link is the center of the robot's bottom plate -->
  <link name="meca_base_link_A">
    <visual>
      <origin xyz="0 0 0" rpy="0 0 0" />
      <geometry>
        <mesh filename="package://mecademic_description/meshes/meca_500_r3_base.dae" />
      </geometry>
    </visual>
    <collision>
      <origin xyz="0 0 0" rpy="0 0 0" />
      <geometry>
        <mesh filename="package://mecademic_description/meshes/meca_500_r3_base_collision.stl" />
      </geometry>
    </collision>
    <inertial>
      <mass value="1"/>
      <inertia ixx="0.01" ixy="0" ixz="0" iyy="0.01" iyz="0" izz="0.01"/>
    </inertial>
  </link>

  <!-- Joint 1 -->
  <link name="meca_axis_1_link_A">
    <visual>
      <origin xyz="0 0 0" rpy="0 0 0" />
      <geometry>
        <mesh filename="package://mecademic_description/meshes/meca_500_r3_j1.dae" />
      </geometry>
    </visual>
    <collision>
      <origin xyz="0 0 0" rpy="0 0 0" />
      <geometry>
        <mesh filename="package://mecademic_description/meshes/meca_500_r3_j1_collision.stl" />
      </geometry>
    </collision>
    <inertial>
      <mass value="1"/>
      <inertia ixx="0.01" ixy="0" ixz="0" iyy="0.01" iyz="0" izz="0.01"/>
    </inertial>
  </link>

  <joint name="meca_axis_1_joint_A" type="revolute">
    <origin xyz="0.012498 0 0.091" rpy="0 0 0" />
    <parent link="meca_base_link_A" />
    <child link="meca_axis_1_link_A" />
    <axis xyz="0 0 1" />
    <limit effort="10.0" velocity="2.61799" lower="-3.05433" upper="3.05433" />
  </joint>

  <!-- Joint 2 -->
  <link name="meca_axis_2_link_A">
    <visual>
      <origin xyz="0 0 0" rpy="0 0 0" />
      <geometry>
        <mesh filename="package://mecademic_description/meshes/meca_500_r3_j2.dae" />
      </geometry>
    </visual>
    <collision>
      <origin xyz="0 0 0" rpy="0 0 0" />
      <geometry>
        <mesh filename="package://mecademic_description/meshes/meca_500_r3_j2_collision.stl" />
      </geometry>
    </collision>
    <inertial>
      <mass value="1"/>
      <inertia ixx="0.01" ixy="0" ixz="0" iyy="0.01" iyz="0" izz="0.01"/>
    </inertial>
  </link>

  <joint name="meca_axis_2_joint_A" type="revolute">
    <origin xyz="0 0 0.044" rpy="0 0 0" />
    <parent link="meca_axis_1_link_A" />
    <child link="meca_axis_2_link_A" />
    <axis xyz="0 1 0" />
    <limit effort="10.0" velocity="2.61799" lower="-1.22173048" upper="1.5708" />
  </joint>

  <!-- Joint 3 -->
  <link name="meca_axis_3_link_A">
    <visual>
      <origin xyz="0 0 0" rpy="0 0 0" />
      <geometry>
        <mesh filename="package://mecademic_description/meshes/meca_500_r3_j3.dae" />
      </geometry>
    </visual>
    <collision>
      <origin xyz="0 0 0" rpy="0 0 0" />
      <geometry>
        <mesh filename="package://mecademic_description/meshes/meca_500_r3_j3_collision.stl" />
      </geometry>
    </collision>
    <inertial>
      <mass value="1"/>
      <inertia ixx="0.01" ixy="0" ixz="0" iyy="0.01" iyz="0" izz="0.01"/>
    </inertial>
  </link>

  <joint name="meca_axis_3_joint_A" type="revolute">
    <origin xyz="0 0 0.135" rpy="0 0 0" />
    <parent link="meca_axis_2_link_A" />
    <child link="meca_axis_3_link_A" />
    <axis xyz="0 1 0" />
    <limit effort="10.0" velocity="3.14159" lower="-2.35619" upper="1.22173048" />
  </joint>

  <!-- Joint 4 -->
  <link name="meca_axis_4_link_A">
    <visual>
      <origin xyz="0 0 0" rpy="0 0 0" />
      <geometry>
        <mesh filename="package://mecademic_description/meshes/meca_500_r3_j4.dae" />
      </geometry>
    </visual>
    <collision>
      <origin xyz="0 0 0" rpy="0 0 0" />
      <geometry>
        <mesh filename="package://mecademic_description/meshes/meca_500_r3_j4_collision.stl" />
      </geometry>
    </collision>
    <inertial>
      <mass value="1"/>
      <inertia ixx="0.01" ixy="0" ixz="0" iyy="0.01" iyz="0" izz="0.01"/>
    </inertial>
  </link>

  <joint name="meca_axis_4_joint_A" type="revolute">
    <origin xyz="0 0 0.038" rpy="0 0 0" />
    <parent link="meca_axis_3_link_A" />
    <child link="meca_axis_4_link_A" />
    <axis xyz="1 0 0" />
    <limit effort="10.0" velocity="5.23599" lower="-2.96706" upper="2.96706" />
  </joint>

  <!-- Joint 5 -->
  <link name="meca_axis_5_link_A">
    <visual>
      <origin xyz="0 0 0" rpy="0 0 0" />
      <geometry>
        <mesh filename="package://mecademic_description/meshes/meca_500_r3_j5.dae" />
      </geometry>
    </visual>
    <collision>
      <origin xyz="0 0 0" rpy="0 0 0" />
      <geometry>
        <mesh filename="package://mecademic_description/meshes/meca_500_r3_j5_collision.stl" />
      </geometry>
    </collision>
    <inertial>
      <mass value="1"/>
      <inertia ixx="0.01" ixy="0" ixz="0" iyy="0.01" iyz="0" izz="0.01"/>
    </inertial>
  </link>

  <joint name="meca_axis_5_joint_A" type="revolute">
    <origin xyz="0.12 0 0" rpy="0 0 0" />
    <parent link="meca_axis_4_link_A" />
    <child link="meca_axis_5_link_A" />
    <axis xyz="0 1 0" />
    <limit effort="10.0" velocity="5.23599" lower="-2.00713" upper="2.00713" />
  </joint>

  <!-- Joint 6 -->
  <link name="meca_axis_6_link_A">
    <visual>
      <origin xyz="0 0 0" rpy="0 0 0" />
      <geometry>
        <mesh filename="package://mecademic_description/meshes/meca_500_r3_j6.dae" />
      </geometry>
    </visual>
    <collision>
      <origin xyz="0 0 0" rpy="0 0 0" />
      <geometry>
        <mesh filename="package://mecademic_description/meshes/meca_500_r3_j6_collision.stl" />
      </geometry>
    </collision>
    <inertial>
      <mass value="1"/>
      <inertia ixx="0.01" ixy="0" ixz="0" iyy="0.01" iyz="0" izz="0.01"/>
    </inertial>
  </link>

  <joint name="meca_axis_6_joint_A" type="revolute">
    <origin xyz="0.07 0 0" rpy="0 0 0" />
    <parent link="meca_axis_5_link_A" />
    <child link="meca_axis_6_link_A" />
    <axis xyz="1 0 0" />
    <limit effort="10.0" velocity="8.72665" lower="-4.712" upper="4.712" />
  </joint>


<!-- 2nd ROBOT -->
  <joint name="world_to_base_B" type="fixed">
      <origin xyz="0.3 0.6 0" rpy="0 0 0"/>
      <parent link="world"/>
      <child link="base_link_B"/>
    </joint>

  <gazebo>
      <plugin filename="libxbot2_gz_joint_server.so" name="xbot2_gz_joint_server">
          <pid>
            <pid name="J1_B" profile="small_mot"/>
            <pid name="meca_axis_1_joint_B" profile="small_mot"/>
            <pid name="meca_axis_2_joint_B" profile="small_mot"/>
            <pid name="meca_axis_3_joint_B" profile="small_mot"/>
            <pid name="meca_axis_4_joint_B" profile="small_mot"/>
            <pid name="meca_axis_5_joint_B" profile="small_mot"/>
            <pid name="meca_axis_6_joint_B" profile="small_mot"/>
          </pid>
          <gain d="5" name="small_mot" p="100"/>
      </plugin>
    </gazebo>
  
  <link name="base_link_B">
    <inertial>
      <mass value="10.0"/>
      <inertia ixx="1.0e-03" ixy="0.0" ixz="0.0" iyy="1.0e-03" iyz="0.0" izz="1.0e-03"/>
    </inertial>
  </link>

  <joint name="fixed_BL4104C_1" type="fixed">
    <axis rpy="0 0 0" xyz="0 0 1"/>
    <parent link="base_link_B"/>
    <child link="BL4104C_1_stator"/>
    <origin rpy="0.0 -0.0 0.0" xyz="0.0 0.0 0.0"/>
  </joint>
  <link name="BL4104C_1_stator">
    <visual>
      <!-- Load mesh. Rotate the origin frame (this is because of how the .stl was saved) -->
      <origin rpy="0.0 0.0 0.0" xyz="0.0 0.0 0.105"/>
      <geometry>
        <cylinder length="0.21" radius="0.13"/>
      </geometry>
      <material name="grey"/>
    </visual>
    <collision>
      <origin rpy="0.0 0.0 0.0" xyz="0.0 0.0 0.105"/>
      <geometry>
        <cylinder length="0.21" radius="0.13"/>
      </geometry>
    </collision>
    <inertial>
      <origin rpy="0 0 0" xyz="0.0 0.0 0.10614489"/>
      <mass value="2.0554934"/>
      <inertia ixx="0.01068855" ixy="-1.14168e-05" ixz="2.71689e-06" iyy="0.010584907" iyz="8.76312e-05" izz="0.0032026258"/>
    </inertial>
  </link>
  <gazebo reference="BL4104C_1_stator">
    <mu1>0.2</mu1>
    <mu2>0.2</mu2>
    <kp>1000000.0</kp>
    <kd>1.0</kd>
    <maxVel>0.0</maxVel>
    <minDepth>0.0001</minDepth>
    <material>Gazebo/Blue</material>
  </gazebo>
  <joint name="J1_B" type="continuous">
    <axis rpy="0 0 0" xyz="0 0 1"/>
    <parent link="BL4104C_1_stator"/>
    <child link="L_1_B"/>
    <origin rpy="0.0 -0.0 0.0" xyz="0.0 0.0 0.21"/>
    <limit effort="147" lower="-2.8" upper="2.8" velocity="100000000"/>
  </joint>
  <!-- <xacro:property name="visual" value="package://sps-pkg/database/modular/meshes/yaw_base.stl"/> -->
  <link name="L_1_B">
    <visual>
      <origin rpy="0.0 0.0 0.0" xyz="0.0 0.0 0.002"/>
      <geometry>
        <cylinder length="0.004" radius="0.063"/>
      </geometry>
      <material name="grey"/>
    </visual>
    <collision>
      <origin rpy="0.0 0.0 0.0" xyz="0.0 0.0 0.002"/>
      <geometry>
        <cylinder length="0.004" radius="0.063"/>
      </geometry>
      <material name="grey"/>
    </collision>
    <inertial>
      <origin rpy="0 0 0" xyz="0.0 0.0 -0.024438213"/>
      <mass value="0.42322395"/>
      <inertia ixx="0.00063746146" ixy="1.1903424e-05" ixz="6.7230372e-07" iyy="0.00064218987" iyz="2.203073e-05" izz="0.001009674"/>
    </inertial>
  </link>
  <joint name="fixed_L_1_B_rotor_fast" type="fixed">
    <axis rpy="0 0 0" xyz="0 0 1"/>
    <parent link="L_1_B"/>
    <child link="L_1_B_rotor_fast"/>
    <origin rpy="0.0 -0.0 0.0" xyz="0.0 0.0 0.0"/>
  </joint>
  <link name="L_1_B_rotor_fast">
    <inertial>
      <origin rpy="0 0 0" xyz="0.0 0.0 -0.0978986"/>
      <mass value="0.197124"/>
      <inertia ixx="0.00016128216" ixy="-2.4229e-07" ixz="3.771218e-06" iyy="0.00016138868" iyz="-2.4900687e-06" izz="0.1287638"/>
      <!-- ixz="0.0003771218" -->
      <!-- iyz="-0.00024900687" -->
      <!-- izz="1.287638e-05" -->
    </inertial>
  </link>

  <joint name="L_1_B_to_meca_base_link_B" type="fixed">
    <parent link="L_1_B"/>
    <child link="meca_base_link_B"/>
    <origin rpy="0 1.571 0" xyz="0.1 0.0 0.05"/>
  </joint>

    <!-- Base link is the center of the robot's bottom plate -->
  <link name="meca_base_link_B">
    <visual>
      <origin xyz="0 0 0" rpy="0 0 0" />
      <geometry>
        <mesh filename="package://mecademic_description/meshes/meca_500_r3_base.dae" />
      </geometry>
    </visual>
    <collision>
      <origin xyz="0 0 0" rpy="0 0 0" />
      <geometry>
        <mesh filename="package://mecademic_description/meshes/meca_500_r3_base_collision.stl" />
      </geometry>
    </collision>
    <inertial>
      <mass value="1"/>
      <inertia ixx="0.01" ixy="0" ixz="0" iyy="0.01" iyz="0" izz="0.01"/>
    </inertial>
  </link>

  <!-- Joint 1 -->
  <link name="meca_axis_1_link_B">
    <visual>
      <origin xyz="0 0 0" rpy="0 0 0" />
      <geometry>
        <mesh filename="package://mecademic_description/meshes/meca_500_r3_j1.dae" />
      </geometry>
    </visual>
    <collision>
      <origin xyz="0 0 0" rpy="0 0 0" />
      <geometry>
        <mesh filename="package://mecademic_description/meshes/meca_500_r3_j1_collision.stl" />
      </geometry>
    </collision>
    <inertial>
      <mass value="1"/>
      <inertia ixx="0.01" ixy="0" ixz="0" iyy="0.01" iyz="0" izz="0.01"/>
    </inertial>
  </link>

  <joint name="meca_axis_1_joint_B" type="revolute">
    <origin xyz="0.012498 0 0.091" rpy="0 0 0" />
    <parent link="meca_base_link_B" />
    <child link="meca_axis_1_link_B" />
    <axis xyz="0 0 1" />
    <limit effort="10.0" velocity="2.61799" lower="-3.05433" upper="3.05433" />
  </joint>

  <!-- Joint 2 -->
  <link name="meca_axis_2_link_B">
    <visual>
      <origin xyz="0 0 0" rpy="0 0 0" />
      <geometry>
        <mesh filename="package://mecademic_description/meshes/meca_500_r3_j2.dae" />
      </geometry>
    </visual>
    <collision>
      <origin xyz="0 0 0" rpy="0 0 0" />
      <geometry>
        <mesh filename="package://mecademic_description/meshes/meca_500_r3_j2_collision.stl" />
      </geometry>
    </collision>
    <inertial>
      <mass value="1"/>
      <inertia ixx="0.01" ixy="0" ixz="0" iyy="0.01" iyz="0" izz="0.01"/>
    </inertial>
  </link>

  <joint name="meca_axis_2_joint_B" type="revolute">
    <origin xyz="0 0 0.044" rpy="0 0 0" />
    <parent link="meca_axis_1_link_B" />
    <child link="meca_axis_2_link_B" />
    <axis xyz="0 1 0" />
    <limit effort="10.0" velocity="2.61799" lower="-1.22173048" upper="1.5708" />
  </joint>

  <!-- Joint 3 -->
  <link name="meca_axis_3_link_B">
    <visual>
      <origin xyz="0 0 0" rpy="0 0 0" />
      <geometry>
        <mesh filename="package://mecademic_description/meshes/meca_500_r3_j3.dae" />
      </geometry>
    </visual>
    <collision>
      <origin xyz="0 0 0" rpy="0 0 0" />
      <geometry>
        <mesh filename="package://mecademic_description/meshes/meca_500_r3_j3_collision.stl" />
      </geometry>
    </collision>
    <inertial>
      <mass value="1"/>
      <inertia ixx="0.01" ixy="0" ixz="0" iyy="0.01" iyz="0" izz="0.01"/>
    </inertial>
  </link>

  <joint name="meca_axis_3_joint_B" type="revolute">
    <origin xyz="0 0 0.135" rpy="0 0 0" />
    <parent link="meca_axis_2_link_B" />
    <child link="meca_axis_3_link_B" />
    <axis xyz="0 1 0" />
    <limit effort="10.0" velocity="3.14159" lower="-2.35619" upper="1.22173048" />
  </joint>

  <!-- Joint 4 -->
  <link name="meca_axis_4_link_B">
    <visual>
      <origin xyz="0 0 0" rpy="0 0 0" />
      <geometry>
        <mesh filename="package://mecademic_description/meshes/meca_500_r3_j4.dae" />
      </geometry>
    </visual>
    <collision>
      <origin xyz="0 0 0" rpy="0 0 0" />
      <geometry>
        <mesh filename="package://mecademic_description/meshes/meca_500_r3_j4_collision.stl" />
      </geometry>
    </collision>
    <inertial>
      <mass value="1"/>
      <inertia ixx="0.01" ixy="0" ixz="0" iyy="0.01" iyz="0" izz="0.01"/>
    </inertial>
  </link>

  <joint name="meca_axis_4_joint_B" type="revolute">
    <origin xyz="0 0 0.038" rpy="0 0 0" />
    <parent link="meca_axis_3_link_B" />
    <child link="meca_axis_4_link_B" />
    <axis xyz="1 0 0" />
    <limit effort="10.0" velocity="5.23599" lower="-2.96706" upper="2.96706" />
  </joint>

  <!-- Joint 5 -->
  <link name="meca_axis_5_link_B">
    <visual>
      <origin xyz="0 0 0" rpy="0 0 0" />
      <geometry>
        <mesh filename="package://mecademic_description/meshes/meca_500_r3_j5.dae" />
      </geometry>
    </visual>
    <collision>
      <origin xyz="0 0 0" rpy="0 0 0" />
      <geometry>
        <mesh filename="package://mecademic_description/meshes/meca_500_r3_j5_collision.stl" />
      </geometry>
    </collision>
    <inertial>
      <mass value="1"/>
      <inertia ixx="0.01" ixy="0" ixz="0" iyy="0.01" iyz="0" izz="0.01"/>
    </inertial>
  </link>

  <joint name="meca_axis_5_joint_B" type="revolute">
    <origin xyz="0.12 0 0" rpy="0 0 0" />
    <parent link="meca_axis_4_link_B" />
    <child link="meca_axis_5_link_B" />
    <axis xyz="0 1 0" />
    <limit effort="10.0" velocity="5.23599" lower="-2.00713" upper="2.00713" />
  </joint>

  <!-- Joint 6 -->
  <link name="meca_axis_6_link_B">
    <visual>
      <origin xyz="0 0 0" rpy="0 0 0" />
      <geometry>
        <mesh filename="package://mecademic_description/meshes/meca_500_r3_j6.dae" />
      </geometry>
    </visual>
    <collision>
      <origin xyz="0 0 0" rpy="0 0 0" />
      <geometry>
        <mesh filename="package://mecademic_description/meshes/meca_500_r3_j6_collision.stl" />
      </geometry>
    </collision>
    <inertial>
      <mass value="1"/>
      <inertia ixx="0.01" ixy="0" ixz="0" iyy="0.01" iyz="0" izz="0.01"/>
    </inertial>
  </link>

  <joint name="meca_axis_6_joint_B" type="revolute">
    <origin xyz="0.07 0 0" rpy="0 0 0" />
    <parent link="meca_axis_5_link_B" />
    <child link="meca_axis_6_link_B" />
    <axis xyz="1 0 0" />
    <limit effort="10.0" velocity="8.72665" lower="-4.712" upper="4.712" />
  </joint>

    <!-- BUFFERS -->
  <joint name="world_to_buffer" type="fixed">
    <origin xyz="0.2 0.25 0" rpy="0 0 0"/>
    <parent link="world"/>
    <child link="buffer_base_link"/>
  </joint>
  
  <link name="buffer_base_link"/>   

  <joint name="buffer_base_to_1" type="fixed">
    <origin xyz="0 0 0" rpy="0 1.571 0"/>
    <parent link="buffer_base_link"/>
    <child link="buffer_1"/>
  </joint>

  <link name="buffer_1"/>

  <joint name="buffer_base_to_2" type="fixed">
        <origin xyz="0.15 0.0 0" rpy="0 1.571 0"/>
        <parent link="buffer_base_link"/>
        <child link="buffer_2"/>
      </joint>

  <link name="buffer_2"/>

  <!-- CANDY MILL -->
  <joint name="world_to_mill" type="fixed">
    <origin xyz="0.7 0.6 0" rpy="0 1.571 0"/>
    <parent link="world"/>
    <child link="mill_base_link"/>
  </joint>
  
  <link name="mill_base_link"/>   

  <joint name="mill_base_to_stick" type="fixed">
    <origin xyz="-0.2 0 0" rpy="0 -1.571 0"/>
    <parent link="mill_base_link"/>
    <child link="mill_stick"/>
  </joint>

  <link name="mill_stick"/>

  <!-- SLIDERS -->
  <joint name="world_to_slider" type="fixed">
    <origin xyz="-0.05 0.05 0" rpy="0 0 0"/>
    <parent link="world"/>
    <child link="slider_base_link"/>
  </joint>
  
  <link name="slider_base_link"/>   

  <joint name="slider_base_to_empty" type="fixed">
    <origin xyz="0 0 0" rpy="0 1.571 0"/>
    <parent link="slider_base_link"/>
    <child link="empty_container"/>
  </joint>

  <link name="empty_container"/>

  <joint name="sliders_base_to_lid" type="fixed">
        <origin xyz="-0.05 0.1 0" rpy="0 1.571 0"/>
        <parent link="slider_base_link"/>
        <child link="lid"/>
      </joint>

  <link name="lid"/>

  <joint name="sliders_base_to_full" type="fixed">
        <origin xyz="0.6 0 0" rpy="0 1.571 0"/>
        <parent link="slider_base_link"/>
        <child link="full_container"/>
      </joint>

  <link name="full_container"/>


</robot>
